<sdf version='1.11'>
  <model name='wheelchair'>
    <link name='base_footprint'>
      <inertial>
        <pose>-0.049709551471288478 3.3039205332383732e-19 0.19563851061803639 0 0 0</pose>
        <mass>10.500999999999999</mass>
        <inertia>
          <ixx>0.53913864378630616</ixx>
          <ixy>-1.90718812781185e-18</ixy>
          <ixz>-0.001331302542615001</ixz>
          <iyy>0.56677025791829339</iyy>
          <iyz>-1.5131956042231551e-20</iyz>
          <izz>0.57521161413198729</izz>
        </inertia>
      </inertial>
      <collision name='base_footprint_fixed_joint_lump__base_link_collision'>
        <pose>-0.050000000000000003 0 0.20000000000000001 0 0 0</pose>
        <geometry>
          <box>
            <size>0.59999999999999998 0.64500000000000002 0.25</size>
          </box>
        </geometry>
        <surface>
          <contact>
            <ode/>
          </contact>
          <friction>
            <ode/>
          </friction>
        </surface>
      </collision>
      <collision name='base_footprint_fixed_joint_lump__left_front_caster_collision_1'>
        <pose>0.29999999999999999 0.23999999999999999 0.035999999999999997 0 0 0</pose>
        <geometry>
          <sphere>
            <radius>0.050000000000000003</radius>
          </sphere>
        </geometry>
      </collision>
      <collision name='base_footprint_fixed_joint_lump__left_rear_caster_collision_2'>
        <pose>-0.40999999999999998 0.23999999999999999 0.035999999999999997 0 0 0</pose>
        <geometry>
          <sphere>
            <radius>0.050000000000000003</radius>
          </sphere>
        </geometry>
      </collision>
      <collision name='base_footprint_fixed_joint_lump__lidar_link_collision_3'>
        <pose>0 0 0.40000000000000002 0 0 0</pose>
        <geometry>
          <cylinder>
            <length>0.050000000000000003</length>
            <radius>0.050000000000000003</radius>
          </cylinder>
        </geometry>
        <surface>
          <contact>
            <ode/>
          </contact>
          <friction>
            <ode/>
          </friction>
        </surface>
      </collision>
      <collision name='base_footprint_fixed_joint_lump__right_front_caster_collision_4'>
        <pose>0.29999999999999999 -0.23999999999999999 0.035999999999999997 0 0 0</pose>
        <geometry>
          <sphere>
            <radius>0.050000000000000003</radius>
          </sphere>
        </geometry>
      </collision>
      <collision name='base_footprint_fixed_joint_lump__right_rear_caster_collision_5'>
        <pose>-0.40999999999999998 -0.23999999999999999 0.035999999999999997 0 0 0</pose>
        <geometry>
          <sphere>
            <radius>0.050000000000000003</radius>
          </sphere>
        </geometry>
      </collision>
      <visual name='base_footprint_fixed_joint_lump__base_link_visual'>
        <pose>-0.050000000000000003 0 0.20000000000000001 0 0 0</pose>
        <geometry>
          <box>
            <size>0.59999999999999998 0.64500000000000002 0.25</size>
          </box>
        </geometry>
        <material>
          <script>
            <name>Gazebo/Green</name>
            <uri>file://media/materials/scripts/gazebo.material</uri>
          </script>
          <diffuse>0 0.75000006 0 1</diffuse>
          <ambient>0 0.75000006 0 1</ambient>
        </material>
      </visual>
      <visual name='base_footprint_fixed_joint_lump__base_link_visual_1'>
        <pose>-0.33250000000000002 0.23999999999999999 0.115 0 0 0</pose>
        <geometry>
          <box>
            <size>0.29999999999999999 0.080000000000000002 0.080000000000000002</size>
          </box>
        </geometry>
        <material>
          <script>
            <name>Gazebo/Green</name>
            <uri>file://media/materials/scripts/gazebo.material</uri>
          </script>
          <diffuse>0 0 0 1</diffuse>
          <ambient>0 0 0 1</ambient>
        </material>
      </visual>
      <visual name='base_footprint_fixed_joint_lump__base_link_visual_2'>
        <pose>-0.33250000000000002 -0.23999999999999999 0.115 0 0 0</pose>
        <geometry>
          <box>
            <size>0.29999999999999999 0.080000000000000002 0.080000000000000002</size>
          </box>
        </geometry>
        <material>
          <script>
            <name>Gazebo/Green</name>
            <uri>file://media/materials/scripts/gazebo.material</uri>
          </script>
          <diffuse>0 0 0 1</diffuse>
          <ambient>0 0 0 1</ambient>
        </material>
      </visual>
      <visual name='base_footprint_fixed_joint_lump__base_link_visual_3'>
        <pose>0.28000000000000003 0.23999999999999999 0.115 0 0 0</pose>
        <geometry>
          <box>
            <size>0.059999999999999998 0.080000000000000002 0.080000000000000002</size>
          </box>
        </geometry>
        <material>
          <script>
            <name>Gazebo/Green</name>
            <uri>file://media/materials/scripts/gazebo.material</uri>
          </script>
          <diffuse>0 0 0 1</diffuse>
          <ambient>0 0 0 1</ambient>
        </material>
      </visual>
      <visual name='base_footprint_fixed_joint_lump__base_link_visual_4'>
        <pose>0.28000000000000003 -0.23999999999999999 0.115 0 0 0</pose>
        <geometry>
          <box>
            <size>0.059999999999999998 0.080000000000000002 0.080000000000000002</size>
          </box>
        </geometry>
        <material>
          <script>
            <name>Gazebo/Green</name>
            <uri>file://media/materials/scripts/gazebo.material</uri>
          </script>
          <diffuse>0 0 0 1</diffuse>
          <ambient>0 0 0 1</ambient>
        </material>
      </visual>
      <visual name='base_footprint_fixed_joint_lump__base_link_visual_5'>
        <pose>-0.33000000000000002 0 0.60000000000000009 0 0 0</pose>
        <geometry>
          <box>
            <size>0.040000000000000001 0.40000000000000002 0.55000000000000004</size>
          </box>
        </geometry>
        <material>
          <script>
            <name>Gazebo/Green</name>
            <uri>file://media/materials/scripts/gazebo.material</uri>
          </script>
          <diffuse>0 0 0 1</diffuse>
          <ambient>0 0 0 1</ambient>
        </material>
      </visual>
      <visual name='base_footprint_fixed_joint_lump__left_front_caster_visual_6'>
        <pose>0.29999999999999999 0.23999999999999999 0.035999999999999997 0 0 0</pose>
        <geometry>
          <sphere>
            <radius>0.050000000000000003</radius>
          </sphere>
        </geometry>
        <material>
          <diffuse>0.875 0.875 0.875 1</diffuse>
          <ambient>0.875 0.875 0.875 1</ambient>
        </material>
      </visual>
      <visual name='base_footprint_fixed_joint_lump__left_rear_caster_visual_7'>
        <pose>-0.40999999999999998 0.23999999999999999 0.035999999999999997 0 0 0</pose>
        <geometry>
          <sphere>
            <radius>0.050000000000000003</radius>
          </sphere>
        </geometry>
        <material>
          <diffuse>0.875 0.875 0.875 1</diffuse>
          <ambient>0.875 0.875 0.875 1</ambient>
        </material>
      </visual>
      <visual name='base_footprint_fixed_joint_lump__lidar_link_visual_8'>
        <pose>0 0 0.40000000000000002 0 0 0</pose>
        <geometry>
          <cylinder>
            <length>0.050000000000000003</length>
            <radius>0.050000000000000003</radius>
          </cylinder>
        </geometry>
        <material>
          <diffuse>0.875 0.875 0.875 1</diffuse>
          <ambient>0.875 0.875 0.875 1</ambient>
        </material>
      </visual>
      <visual name='base_footprint_fixed_joint_lump__right_front_caster_visual_9'>
        <pose>0.29999999999999999 -0.23999999999999999 0.035999999999999997 0 0 0</pose>
        <geometry>
          <sphere>
            <radius>0.050000000000000003</radius>
          </sphere>
        </geometry>
        <material>
          <diffuse>0.875 0.875 0.875 1</diffuse>
          <ambient>0.875 0.875 0.875 1</ambient>
        </material>
      </visual>
      <visual name='base_footprint_fixed_joint_lump__right_rear_caster_visual_10'>
        <pose>-0.40999999999999998 -0.23999999999999999 0.035999999999999997 0 0 0</pose>
        <geometry>
          <sphere>
            <radius>0.050000000000000003</radius>
          </sphere>
        </geometry>
        <material>
          <diffuse>0.875 0.875 0.875 1</diffuse>
          <ambient>0.875 0.875 0.875 1</ambient>
        </material>
      </visual>
      <sensor name='lidar' type='gpu_lidar'>
        <topic>scan</topic>
        <update_rate>10</update_rate>
        <lidar>
          <scan>
            <horizontal>
              <samples>360</samples>
              <resolution>1</resolution>
              <min_angle>-3.1415899999999999</min_angle>
              <max_angle>3.1415899999999999</max_angle>
            </horizontal>
          </scan>
          <range>
            <min>0.12</min>
            <max>10</max>
            <resolution>0.01</resolution>
          </range>
          <noise>
            <type>gaussian</type>
            <mean>0</mean>
            <stddev>0.01</stddev>
          </noise>
        </lidar>
        <always_on>true</always_on>
        <visualize>true</visualize>
        <pose>0 0 0.40000000000000002 0 0 0</pose>
      </sensor>
    </link>
    <joint name='base_left_wheel_joint' type='revolute'>
      <pose relative_to='base_footprint'>0 0.34749999999999998 0.16400000000000001 0 0 0</pose>
      <parent>base_footprint</parent>
      <child>left_wheel</child>
      <axis>
        <xyz>0 1 0</xyz>
        <limit>
          <lower>-inf</lower>
          <upper>inf</upper>
        </limit>
        <dynamics>
          <spring_reference>0</spring_reference>
          <spring_stiffness>0</spring_stiffness>
        </dynamics>
      </axis>
    </joint>
    <link name='left_wheel'>
      <pose relative_to='base_left_wheel_joint'>0 0 0 0 0 0</pose>
      <inertial>
        <pose>0 0 0 0 0 0</pose>
        <mass>0.5</mass>
        <inertia>
          <ixx>0.001</ixx>
          <ixy>0</ixy>
          <ixz>0</ixz>
          <iyy>0.001</iyy>
          <iyz>0</iyz>
          <izz>0.001</izz>
        </inertia>
      </inertial>
      <collision name='left_wheel_collision'>
        <pose>0 0 0 1.5708 0 0</pose>
        <geometry>
          <cylinder>
            <length>0.050000000000000003</length>
            <radius>0.17799999999999999</radius>
          </cylinder>
        </geometry>
        <surface>
          <contact>
            <ode/>
          </contact>
          <friction>
            <ode>
              <mu>1</mu>
              <mu2>1</mu2>
            </ode>
          </friction>
        </surface>
      </collision>
      <visual name='left_wheel_visual'>
        <pose>0 0 0 1.5708 0 0</pose>
        <geometry>
          <cylinder>
            <length>0.050000000000000003</length>
            <radius>0.17799999999999999</radius>
          </cylinder>
        </geometry>
        <material>
          <script>
            <name>Gazebo/Grey</name>
            <uri>file://media/materials/scripts/gazebo.material</uri>
          </script>
          <diffuse>0.875 0.875 0.875 1</diffuse>
          <ambient>0.875 0.875 0.875 1</ambient>
        </material>
      </visual>
    </link>
    <joint name='base_right_wheel_joint' type='revolute'>
      <pose relative_to='base_footprint'>0 -0.34749999999999998 0.16400000000000001 0 0 0</pose>
      <parent>base_footprint</parent>
      <child>right_wheel</child>
      <axis>
        <xyz>0 1 0</xyz>
        <limit>
          <lower>-inf</lower>
          <upper>inf</upper>
        </limit>
        <dynamics>
          <spring_reference>0</spring_reference>
          <spring_stiffness>0</spring_stiffness>
        </dynamics>
      </axis>
    </joint>
    <link name='right_wheel'>
      <pose relative_to='base_right_wheel_joint'>0 0 0 0 0 0</pose>
      <inertial>
        <pose>0 0 0 0 0 0</pose>
        <mass>0.5</mass>
        <inertia>
          <ixx>0.001</ixx>
          <ixy>0</ixy>
          <ixz>0</ixz>
          <iyy>0.001</iyy>
          <iyz>0</iyz>
          <izz>0.001</izz>
        </inertia>
      </inertial>
      <collision name='right_wheel_collision'>
        <pose>0 0 0 1.5708 0 0</pose>
        <geometry>
          <cylinder>
            <length>0.050000000000000003</length>
            <radius>0.17799999999999999</radius>
          </cylinder>
        </geometry>
        <surface>
          <contact>
            <ode/>
          </contact>
          <friction>
            <ode>
              <mu>1</mu>
              <mu2>1</mu2>
            </ode>
          </friction>
        </surface>
      </collision>
      <visual name='right_wheel_visual'>
        <pose>0 0 0 1.5708 0 0</pose>
        <geometry>
          <cylinder>
            <length>0.050000000000000003</length>
            <radius>0.17799999999999999</radius>
          </cylinder>
        </geometry>
        <material>
          <script>
            <name>Gazebo/Grey</name>
            <uri>file://media/materials/scripts/gazebo.material</uri>
          </script>
          <diffuse>0.875 0.875 0.875 1</diffuse>
          <ambient>0.875 0.875 0.875 1</ambient>
        </material>
      </visual>
    </link>
    <plugin name='gz::sim::systems::DiffDrive' filename='gz-sim-diff-drive-system'>
      <left_joint>base_left_wheel_joint</left_joint>
      <right_joint>base_right_wheel_joint</right_joint>
      <wheel_separation>0.695</wheel_separation>
      <wheel_radius>0.178</wheel_radius>
      <odom_publish_frequency>50</odom_publish_frequency>
      <topic>cmd_vel</topic>
      <odom_topic>odom</odom_topic>
      <frame_id>odom</frame_id>
      <child_frame_id>base_footprint</child_frame_id>
    </plugin>
    <plugin name='gz::sim::systems::JointStatePublisher' filename='gz-sim-joint-state-publisher-system'/>
    <frame name='left_front_caster_joint' attached_to='base_link'>
      <pose>0.29999999999999999 0.23999999999999999 -0.16400000000000001 0 0 0</pose>
    </frame>
    <frame name='left_front_caster' attached_to='left_front_caster_joint'>
      <pose>0 0 0 0 0 0</pose>
    </frame>
    <frame name='left_rear_caster_joint' attached_to='base_link'>
      <pose>-0.40999999999999998 0.23999999999999999 -0.16400000000000001 0 0 0</pose>
    </frame>
    <frame name='left_rear_caster' attached_to='left_rear_caster_joint'>
      <pose>0 0 0 0 0 0</pose>
    </frame>
    <frame name='lidar_joint' attached_to='base_link'>
      <pose>0 0 0.20000000000000001 0 0 0</pose>
    </frame>
    <frame name='lidar_link' attached_to='lidar_joint'>
      <pose>0 0 0 0 0 0</pose>
    </frame>
    <frame name='right_front_caster_joint' attached_to='base_link'>
      <pose>0.29999999999999999 -0.23999999999999999 -0.16400000000000001 0 0 0</pose>
    </frame>
    <frame name='right_front_caster' attached_to='right_front_caster_joint'>
      <pose>0 0 0 0 0 0</pose>
    </frame>
    <frame name='right_rear_caster_joint' attached_to='base_link'>
      <pose>-0.40999999999999998 -0.23999999999999999 -0.16400000000000001 0 0 0</pose>
    </frame>
    <frame name='right_rear_caster' attached_to='right_rear_caster_joint'>
      <pose>0 0 0 0 0 0</pose>
    </frame>
    <frame name='base_joint' attached_to='base_footprint'>
      <pose>0 0 0.20000000000000001 0 0 0</pose>
    </frame>
    <frame name='base_link' attached_to='base_joint'>
      <pose>0 0 0 0 0 0</pose>
    </frame>
  </model>
</sdf>
